<?xml version="1.0"?>
<!-- =================================================================================== -->
<!-- |    This document was autogenerated by xacro from /keti_ws/install/xarm_description/share/xarm_description/urdf/xarm_device.urdf.xacro | -->
<!-- |    EDITING THIS FILE BY HAND IS NOT RECOMMENDED                                 | -->
<!-- =================================================================================== -->
<robot name="xarm_device">
  <!-- Insert at the beginning of xarm_device_macro.xacro -->
  <material name="xarm6_Black">
    <color rgba="0.0 0.0 0.0 1.0"/>
  </material>
  <material name="xarm6_Red">
    <color rgba="0.8 0.0 0.0 1.0"/>
  </material>
  <material name="xarm6_White">
    <color rgba="1.0 1.0 1.0 1.0"/>
  </material>
  <material name="xarm6_Silver">
    <color rgba="0.753 0.753 0.753 1.0"/>
  </material>
  <material name="Red">
    <color rgba="1.0 0.0 0.0 1.0"/>
  </material>
  <link name="xarm_device"/>
  <joint name="xarm6_world_joint" type="fixed">
    <parent link="xarm_device"/>
    <child link="xarm6_link_base"/>
    <origin rpy="0 0 0" xyz="0 0 0"/>
  </joint>
  <ros2_control name="xarm6_ign_ros2_control/IgnitionSystem" type="system">
    <hardware>
      <plugin>ign_ros2_control/IgnitionSystem</plugin>
      <!-- fake -->
      <!-- <plugin>fake_components/GenericSystem</plugin> -->
      <!-- gazebo -->
      <!-- <plugin>gazebo_ros2_control/GazeboSystem</plugin> -->
      <!-- real xarm -->
      <!-- <plugin>uf_robot_hardware/UFRobotSystemHardware</plugin> -->
    </hardware>
    <joint name="xarm6_joint1">
      <command_interface name="position">
        <param name="min">-31.41592653589793</param>
        <param name="max">31.41592653589793</param>
      </command_interface>
      <command_interface name="velocity">
        <param name="min">-0.2</param>
        <param name="max">0.2</param>
      </command_interface>
      <state_interface name="position">
        <param name="initial_value">0.0</param>
      </state_interface>
      <state_interface name="velocity"/>
      <!-- <state_interface name="effort"/> -->
    </joint>
    <joint name="xarm6_joint2">
      <command_interface name="position">
        <param name="min">-31.41592653589793</param>
        <param name="max">31.41592653589793</param>
      </command_interface>
      <command_interface name="velocity">
        <param name="min">-0.2</param>
        <param name="max">0.2</param>
      </command_interface>
      <state_interface name="position">
        <param name="initial_value">-0.78</param>
      </state_interface>
      <state_interface name="velocity"/>
      <!-- <state_interface name="effort"/> -->
    </joint>
    <joint name="xarm6_joint3">
      <command_interface name="position">
        <param name="min">-31.41592653589793</param>
        <param name="max">31.41592653589793</param>
      </command_interface>
      <command_interface name="velocity">
        <param name="min">-0.2</param>
        <param name="max">0.2</param>
      </command_interface>
      <state_interface name="position">
        <param name="initial_value">-0.78</param>
      </state_interface>
      <state_interface name="velocity"/>
      <!-- <state_interface name="effort"/> -->
    </joint>
    <joint name="xarm6_joint4">
      <command_interface name="position">
        <param name="min">-31.41592653589793</param>
        <param name="max">31.41592653589793</param>
      </command_interface>
      <command_interface name="velocity">
        <param name="min">-0.2</param>
        <param name="max">0.2</param>
      </command_interface>
      <state_interface name="position">
        <param name="initial_value">0.0</param>
      </state_interface>
      <state_interface name="velocity"/>
      <!-- <state_interface name="effort"/> -->
    </joint>
    <joint name="xarm6_joint5">
      <command_interface name="position">
        <param name="min">-31.41592653589793</param>
        <param name="max">31.41592653589793</param>
      </command_interface>
      <command_interface name="velocity">
        <param name="min">-0.2</param>
        <param name="max">0.2</param>
      </command_interface>
      <state_interface name="position">
        <param name="initial_value">1.5708</param>
      </state_interface>
      <state_interface name="velocity"/>
      <!-- <state_interface name="effort"/> -->
    </joint>
    <joint name="xarm6_joint6">
      <command_interface name="position">
        <param name="min">-31.41592653589793</param>
        <param name="max">31.41592653589793</param>
      </command_interface>
      <command_interface name="velocity">
        <param name="min">-0.2</param>
        <param name="max">0.2</param>
      </command_interface>
      <state_interface name="position">
        <param name="initial_value">0.0</param>
      </state_interface>
      <state_interface name="velocity"/>
      <!-- <state_interface name="effort"/> -->
    </joint>
    <!-- Gripper drive joint -->
    <joint name="xarm6_drive_joint">
      <command_interface name="position">
        <param name="min">0</param>
        <param name="max">0.85</param>
      </command_interface>
      <command_interface name="velocity">
        <param name="min">-2.0</param>
        <param name="max">2.0</param>
      </command_interface>
      <state_interface name="position">
        <param name="initial_value">0.85</param>
      </state_interface>
      <state_interface name="velocity"/>
    </joint>
  </ros2_control>
  <link name="xarm6_link_base">
    <inertial>
      <origin rpy="0 0 0" xyz="0.0 0.0 0.09103"/>
      <mass value="2.7"/>
      <inertia ixx="0.00494875" ixy="-3.5E-06" ixz="1.25E-05" iyy="0.00494174" iyz="1.67E-06" izz="0.002219"/>
    </inertial>
    <visual>
      <geometry>
        <mesh filename="package://xarm_description/meshes/xarm6/visual/link_base.stl"/>
      </geometry>
      <origin rpy="0 0 0" xyz="0 0 0"/>
      <material name="xarm6_White"/>
    </visual>
    <collision>
      <geometry>
        <mesh filename="package://xarm_description/meshes/xarm6/visual/link_base.stl"/>
      </geometry>
      <origin rpy="0 0 0" xyz="0 0 0"/>
    </collision>
  </link>
  <link name="xarm6_link1">
    <inertial>
      <origin rpy="0 0 0" xyz="0.00022 0.02951 -0.0124"/>
      <mass value="2.3814"/>
      <inertia ixx="0.0058562" ixy="-1.79e-05" ixz="3.55e-06" iyy="0.0050316" iyz="-0.000888336" izz="0.003536652"/>
    </inertial>
    <visual>
      <geometry>
        <mesh filename="package://xarm_description/meshes/xarm6/visual/link1.stl"/>
      </geometry>
      <origin rpy="0 0 0" xyz="0 0 0"/>
      <material name="xarm6_White"/>
    </visual>
    <collision>
      <geometry>
        <mesh filename="package://xarm_description/meshes/xarm6/visual/link1.stl"/>
      </geometry>
      <origin rpy="0 0 0" xyz="0 0 0"/>
    </collision>
  </link>
  <joint name="xarm6_joint1" type="revolute">
    <parent link="xarm6_link_base"/>
    <child link="xarm6_link1"/>
    <origin rpy="0 0 0" xyz="0 0 0.267"/>
    <axis xyz="0 0 1"/>
    <limit effort="50.0" lower="-31.41592653589793" upper="31.41592653589793" velocity="3.14"/>
    <dynamics damping="1.0" friction="1.0"/>
    <initial_position>0.0</initial_position>
  </joint>
  <link name="xarm6_link2">
    <inertial>
      <origin rpy="0 0 0" xyz="0.03881 -0.22783 0.03496"/>
      <mass value="2.2675"/>
      <inertia ixx="0.028315776" ixy="0.005" ixz="0.00066546" iyy="0.0058" iyz="-0.0045741" izz="0.0273447"/>
    </inertial>
    <visual>
      <geometry>
        <mesh filename="package://xarm_description/meshes/xarm6/visual/link2.stl"/>
      </geometry>
      <origin rpy="0 0 0" xyz="0 0 0"/>
      <material name="xarm6_White"/>
    </visual>
    <collision>
      <geometry>
        <mesh filename="package://xarm_description/meshes/xarm6/visual/link2.stl"/>
      </geometry>
      <origin rpy="0 0 0" xyz="0 0 0"/>
    </collision>
  </link>
  <joint name="xarm6_joint2" type="revolute">
    <parent link="xarm6_link1"/>
    <child link="xarm6_link2"/>
    <origin rpy="-1.5708 0 0" xyz="0 0 0"/>
    <axis xyz="0 0 1"/>
    <limit effort="50.0" lower="-31.41592653589793" upper="31.41592653589793" velocity="3.14"/>
    <dynamics damping="1.0" friction="1.0"/>
    <initial_position>-0.78</initial_position>
  </joint>
  <link name="xarm6_link3">
    <inertial>
      <origin rpy="0 0 0" xyz="0.07041 0.11631 0.0107"/>
      <mass value="1.875"/>
      <inertia ixx="0.0063483" ixy="-0.0015397" ixz="0.00096858" iyy="0.00379758" iyz="0.00186567" izz="0.00595768"/>
    </inertial>
    <visual>
      <geometry>
        <mesh filename="package://xarm_description/meshes/xarm6/visual/link3.stl"/>
      </geometry>
      <origin rpy="0 0 0" xyz="0 0 0"/>
      <material name="xarm6_White"/>
    </visual>
    <collision>
      <geometry>
        <mesh filename="package://xarm_description/meshes/xarm6/visual/link3.stl"/>
      </geometry>
      <origin rpy="0 0 0" xyz="0 0 0"/>
    </collision>
  </link>
  <joint name="xarm6_joint3" type="revolute">
    <parent link="xarm6_link2"/>
    <child link="xarm6_link3"/>
    <origin rpy="0 0 0" xyz="0.0535 -0.2845 0"/>
    <axis xyz="0 0 1"/>
    <limit effort="32.0" lower="-31.41592653589793" upper="31.41592653589793" velocity="3.14"/>
    <dynamics damping="1.0" friction="1.0"/>
    <initial_position>-0.78</initial_position>
  </joint>
  <link name="xarm6_link4">
    <inertial>
      <origin rpy="0 0 0" xyz="-0.00018 0.01798 -0.02291"/>
      <mass value="1.3192"/>
      <inertia ixx="0.004896" ixy="-6.925e-06" ixz="-1.418e-05" iyy="0.00445694" iyz="-0.00023186" izz="0.00134332"/>
    </inertial>
    <visual>
      <geometry>
        <mesh filename="package://xarm_description/meshes/xarm6/visual/link4.stl"/>
      </geometry>
      <origin rpy="0 0 0" xyz="0 0 0"/>
      <material name="xarm6_White"/>
    </visual>
    <collision>
      <geometry>
        <mesh filename="package://xarm_description/meshes/xarm6/visual/link4.stl"/>
      </geometry>
      <origin rpy="0 0 0" xyz="0 0 0"/>
    </collision>
  </link>
  <joint name="xarm6_joint4" type="revolute">
    <parent link="xarm6_link3"/>
    <child link="xarm6_link4"/>
    <origin rpy="-1.5708 0 0" xyz="0.0775 0.3425 0"/>
    <axis xyz="0 0 1"/>
    <limit effort="32.0" lower="-31.41592653589793" upper="31.41592653589793" velocity="3.14"/>
    <dynamics damping="1.0" friction="1.0"/>
    <initial_position>0.0</initial_position>
  </joint>
  <link name="xarm6_link5">
    <inertial>
      <origin rpy="0 0 0" xyz="0.0651 0.03096 0.00315"/>
      <mass value="1.33854"/>
      <inertia ixx="0.00146378" ixy="-0.000450624" ixz="0.000284306" iyy="0.00184192" iyz="0.000130866" izz="0.002333524"/>
    </inertial>
    <visual>
      <geometry>
        <mesh filename="package://xarm_description/meshes/xarm6/visual/link5.stl"/>
      </geometry>
      <origin rpy="0 0 0" xyz="0 0 0"/>
      <material name="xarm6_White"/>
    </visual>
    <collision>
      <geometry>
        <mesh filename="package://xarm_description/meshes/xarm6/visual/link5.stl"/>
      </geometry>
      <origin rpy="0 0 0" xyz="0 0 0"/>
    </collision>
  </link>
  <joint name="xarm6_joint5" type="revolute">
    <parent link="xarm6_link4"/>
    <child link="xarm6_link5"/>
    <origin rpy="1.5708 0 0" xyz="0 0 0"/>
    <axis xyz="0 0 1"/>
    <limit effort="32.0" lower="-31.41592653589793" upper="31.41592653589793" velocity="3.14"/>
    <dynamics damping="1.0" friction="1.0"/>
    <initial_position>1.5708</initial_position>
  </joint>
  <link name="xarm6_link6">
    <inertial>
      <origin rpy="0 0 0" xyz="0 -0.00677 -0.01098"/>
      <mass value="0.17"/>
      <inertia ixx="9.3e-05" ixy="-0.0" ixz="-0.0" iyy="5.87e-05" iyz="-3.6e-06" izz="0.000132"/>
    </inertial>
    <visual>
      <geometry>
        <mesh filename="package://xarm_description/meshes/xarm6/visual/link6.stl"/>
      </geometry>
      <origin rpy="0 0 0" xyz="0 0 0"/>
      <material name="xarm6_Silver"/>
    </visual>
    <collision>
      <geometry>
        <mesh filename="package://xarm_description/meshes/end_tool/collision/end_tool.stl"/>
      </geometry>
      <origin rpy="0 0 0" xyz="0 0 0"/>
    </collision>
  </link>
  <joint name="xarm6_joint6" type="revolute">
    <parent link="xarm6_link5"/>
    <child link="xarm6_link6"/>
    <origin rpy="-1.5708 0 0" xyz="0.076 0.097 0"/>
    <axis xyz="0 0 1"/>
    <limit effort="20.0" lower="-31.41592653589793" upper="31.41592653589793" velocity="3.14"/>
    <dynamics damping="1.0" friction="1.0"/>
    <initial_position>0.0</initial_position>
  </joint>
  <!-- Gripper components -->
  <joint name="xarm6_gripper_fix" type="fixed">
    <parent link="xarm6_link6"/>
    <child link="xarm6_xarm_gripper_base_link"/>
    <origin rpy="0 0 0" xyz="0 0 0"/>
  </joint>
  <link name="xarm6_xarm_gripper_base_link">
    <inertial>
      <origin rpy="0 0 0" xyz="-0.00065489 -0.0018497 0.048028"/>
      <mass value="0.54156"/>
      <inertia ixx="0.00047106" ixy="3.9292E-07" ixz="2.6537E-06" iyy="0.00033072" iyz="-1.0975E-05" izz="0.00025642"/>
    </inertial>
    <visual>
      <origin rpy="0 0 0" xyz="0 0 0"/>
      <geometry>
        <mesh filename="package://xarm_description/meshes/gripper/base_link.stl"/>
      </geometry>
      <material name="xarm6_White"/>
    </visual>
    <collision>
      <origin rpy="0 0 0" xyz="0 0 0"/>
      <geometry>
        <mesh filename="package://xarm_description/meshes/gripper/base_link.stl"/>
      </geometry>
    </collision>
  </link>
  <link name="xarm6_left_outer_knuckle">
    <inertial>
      <origin rpy="0 0 0" xyz="2.9948E-14 0.021559 0.015181"/>
      <mass value="0.033618"/>
      <inertia ixx="1.9111E-05" ixy="-1.8803E-17" ixz="-1.1002E-17" iyy="6.6256E-06" iyz="-7.3008E-06" izz="1.3185E-05"/>
    </inertial>
    <visual>
      <origin rpy="0 0 0" xyz="0 0 0"/>
      <geometry>
        <mesh filename="package://xarm_description/meshes/gripper/left_outer_knuckle.stl"/>
      </geometry>
      <material name="xarm6_Silver"/>
    </visual>
    <collision>
      <origin rpy="0 0 0" xyz="0 0 0"/>
      <geometry>
        <mesh filename="package://xarm_description/meshes/gripper/left_outer_knuckle.stl"/>
      </geometry>
    </collision>
  </link>
  <joint name="xarm6_drive_joint" type="fixed">
    <origin rpy="0.85 0 0" xyz="0 0.035 0.059098"/>
    <parent link="xarm6_xarm_gripper_base_link"/>
    <child link="xarm6_left_outer_knuckle"/>
  </joint>
  <link name="xarm6_left_finger">
    <inertial>
      <origin rpy="0 0 0" xyz="-2.4536E-14 -0.016413 0.029258"/>
      <mass value="0.048304"/>
      <inertia ixx="1.7493E-05" ixy="-4.2156E-19" ixz="6.9164E-18" iyy="1.7225E-05" iyz="4.6433E-06" izz="5.1466E-06"/>
    </inertial>
    <visual>
      <origin rpy="0 0 0" xyz="0 0 0"/>
      <geometry>
        <mesh filename="package://xarm_description/meshes/gripper/left_finger.stl"/>
      </geometry>
      <material name="xarm6_Silver"/>
    </visual>
    <collision>
      <origin rpy="0 0 0" xyz="0 0 0"/>
      <geometry>
        <mesh filename="package://xarm_description/meshes/gripper/left_finger.stl"/>
      </geometry>
    </collision>
  </link>
  <joint name="xarm6_left_finger_joint" type="fixed">
    <origin rpy="-0.85 0 0" xyz="0 0.035465 0.042039"/>
    <parent link="xarm6_left_outer_knuckle"/>
    <child link="xarm6_left_finger"/>
  </joint>
  <link name="xarm6_left_inner_knuckle">
    <inertial>
      <origin rpy="0 0 0" xyz="1.86600784687907E-06 0.0220467847633621 0.0261334672830885"/>
      <mass value="0.0230125781256706"/>
      <inertia ixx="6.09490024271906E-06" ixy="6.06651326160071E-11" ixz="7.19102670500635E-11" iyy="6.01955084375188E-06" iyz="-2.75316812991721E-06" izz="5.07862004479903E-06"/>
    </inertial>
    <visual>
      <origin rpy="0 0 0" xyz="0 0 0"/>
      <geometry>
        <mesh filename="package://xarm_description/meshes/gripper/left_inner_knuckle.stl"/>
      </geometry>
      <material name="xarm6_Silver"/>
    </visual>
    <collision>
      <origin rpy="0 0 0" xyz="0 0 0"/>
      <geometry>
        <mesh filename="package://xarm_description/meshes/gripper/left_inner_knuckle.stl"/>
      </geometry>
    </collision>
  </link>
  <joint name="xarm6_left_inner_knuckle_joint" type="fixed">
    <origin rpy="0.85 0 0" xyz="0 0.02 0.074098"/>
    <parent link="xarm6_xarm_gripper_base_link"/>
    <child link="xarm6_left_inner_knuckle"/>
  </joint>
  <link name="xarm6_right_outer_knuckle">
    <inertial>
      <origin rpy="0 0 0" xyz="-3.1669E-14 -0.021559 0.015181"/>
      <mass value="0.033618"/>
      <inertia ixx="1.9111E-05" ixy="-1.8789E-17" ixz="1.0986E-17" iyy="6.6256E-06" iyz="7.3008E-06" izz="1.3185E-05"/>
    </inertial>
    <visual>
      <origin rpy="0 0 0" xyz="0 0 0"/>
      <geometry>
        <mesh filename="package://xarm_description/meshes/gripper/right_outer_knuckle.stl"/>
      </geometry>
      <material name="xarm6_Silver"/>
    </visual>
    <collision>
      <origin rpy="0 0 0" xyz="0 0 0"/>
      <geometry>
        <mesh filename="package://xarm_description/meshes/gripper/right_outer_knuckle.stl"/>
      </geometry>
    </collision>
  </link>
  <joint name="xarm6_right_outer_knuckle_joint" type="fixed">
    <origin rpy="-0.85 0 0" xyz="0 -0.035 0.059098"/>
    <parent link="xarm6_xarm_gripper_base_link"/>
    <child link="xarm6_right_outer_knuckle"/>
  </joint>
  <link name="xarm6_right_finger">
    <inertial>
      <origin rpy="0 0 0" xyz="2.5618E-14 0.016413 0.029258"/>
      <mass value="0.048304"/>
      <inertia ixx="1.7493E-05" ixy="-5.0014E-19" ixz="-7.5079E-18" iyy="1.7225E-05" iyz="-4.6435E-06" izz="5.1466E-06"/>
    </inertial>
    <visual>
      <origin rpy="0 0 0" xyz="0 0 0"/>
      <geometry>
        <mesh filename="package://xarm_description/meshes/gripper/right_finger.stl"/>
      </geometry>
      <material name="xarm6_Silver"/>
    </visual>
    <collision>
      <origin rpy="0 0 0" xyz="0 0 0"/>
      <geometry>
        <mesh filename="package://xarm_description/meshes/gripper/right_finger.stl"/>
      </geometry>
    </collision>
  </link>
  <joint name="xarm6_right_finger_joint" type="fixed">
    <origin rpy="0.85 0 0" xyz="0 -0.035465 0.042039"/>
    <parent link="xarm6_right_outer_knuckle"/>
    <child link="xarm6_right_finger"/>
  </joint>
  <link name="xarm6_right_inner_knuckle">
    <inertial>
      <origin rpy="0 0 0" xyz="1.866E-06 -0.022047 0.026133"/>
      <mass value="0.023013"/>
      <inertia ixx="6.0949E-06" ixy="-6.0665E-11" ixz="7.191E-11" iyy="6.0197E-06" iyz="2.7531E-06" izz="5.0784E-06"/>
    </inertial>
    <visual>
      <origin rpy="0 0 0" xyz="0 0 0"/>
      <geometry>
        <mesh filename="package://xarm_description/meshes/gripper/right_inner_knuckle.stl"/>
      </geometry>
      <material name="xarm6_Silver"/>
    </visual>
    <collision>
      <origin rpy="0 0 0" xyz="0 0 0"/>
      <geometry>
        <mesh filename="package://xarm_description/meshes/gripper/right_inner_knuckle.stl"/>
      </geometry>
    </collision>
  </link>
  <joint name="xarm6_right_inner_knuckle_joint" type="fixed">
    <origin rpy="-0.85 0 0" xyz="0 -0.02 0.074098"/>
    <parent link="xarm6_xarm_gripper_base_link"/>
    <child link="xarm6_right_inner_knuckle"/>
  </joint>
 <transmission name="xarm6_tran1">
    <type>transmission_interface/SimpleTransmission</type>
    <joint name="xarm6_joint1">
      <hardwareInterface>hardware_interface/PositionJointInterface</hardwareInterface>
    </joint>
    <actuator name="xarm6_motor1">
      <hardwareInterface>hardware_interface/PositionJointInterface</hardwareInterface>
      <mechanicalReduction>100</mechanicalReduction>
    </actuator>
  </transmission>
  <transmission name="xarm6_tran2">
    <type>transmission_interface/SimpleTransmission</type>
    <joint name="xarm6_joint2">
      <hardwareInterface>hardware_interface/PositionJointInterface</hardwareInterface>
    </joint>
    <actuator name="xarm6_motor2">
      <hardwareInterface>hardware_interface/PositionJointInterface</hardwareInterface>
      <mechanicalReduction>100</mechanicalReduction>
    </actuator>
  </transmission>
  <transmission name="xarm6_tran3">
    <type>transmission_interface/SimpleTransmission</type>
    <joint name="xarm6_joint3">
      <hardwareInterface>hardware_interface/PositionJointInterface</hardwareInterface>
    </joint>
    <actuator name="xarm6_motor3">
      <hardwareInterface>hardware_interface/PositionJointInterface</hardwareInterface>
      <mechanicalReduction>100</mechanicalReduction>
    </actuator>
  </transmission>
  <transmission name="xarm6_tran4">
    <type>transmission_interface/SimpleTransmission</type>
    <joint name="xarm6_joint4">
      <hardwareInterface>hardware_interface/PositionJointInterface</hardwareInterface>
    </joint>
    <actuator name="xarm6_motor4">
      <hardwareInterface>hardware_interface/PositionJointInterface</hardwareInterface>
      <mechanicalReduction>100</mechanicalReduction>
    </actuator>
  </transmission>
  <transmission name="xarm6_tran5">
    <type>transmission_interface/SimpleTransmission</type>
    <joint name="xarm6_joint5">
      <hardwareInterface>hardware_interface/PositionJointInterface</hardwareInterface>
    </joint>
    <actuator name="xarm6_motor5">
      <hardwareInterface>hardware_interface/PositionJointInterface</hardwareInterface>
      <mechanicalReduction>100</mechanicalReduction>
    </actuator>
  </transmission>
  <transmission name="xarm6_tran6">
    <type>transmission_interface/SimpleTransmission</type>
    <joint name="xarm6_joint6">
      <hardwareInterface>hardware_interface/PositionJointInterface</hardwareInterface>
    </joint>
    <actuator name="xarm6_motor6">
      <hardwareInterface>hardware_interface/PositionJointInterface</hardwareInterface>
      <mechanicalReduction>100</mechanicalReduction>
    </actuator>
  </transmission>
  <gazebo reference="xarm6_link_base">
    <selfCollide>true</selfCollide>
  </gazebo>
  <gazebo reference="xarm6_link1">
    <selfCollide>true</selfCollide>
  </gazebo>
  <gazebo reference="xarm6_link2">
    <selfCollide>true</selfCollide>
  </gazebo>
  <gazebo reference="xarm6_link3">
    <selfCollide>true</selfCollide>
  </gazebo>
  <gazebo reference="xarm6_link4">
    <selfCollide>true</selfCollide>
  </gazebo>
  <gazebo reference="xarm6_link5">
    <selfCollide>true</selfCollide>
  </gazebo>
  <gazebo reference="xarm6_link6">
    <selfCollide>true</selfCollide>
  </gazebo>

  <!-- Gripper end-effector tip -->
  <link name="xarm6_ee_tip">
    <visual>
      <geometry>
        <sphere radius="0.012"/>
      </geometry>
      <material name="Red"/>
    </visual>
    <collision>
      <geometry>
        <sphere radius="0.005"/>
      </geometry>
    </collision>
  </link>

  <joint name="xarm6_ee_tip_joint" type="fixed">
    <origin rpy="0 0 0" xyz="0.0 0.0 0.17"/>
    <parent link="xarm6_xarm_gripper_base_link"/>
    <child link="xarm6_ee_tip"/>
    <axis xyz="0 0 0"/>
  </joint>

  <!-- <link name="xarm6_ee_tip"/>
  <joint name="xarm6_ee_tip_joint" type="fixed">
    <origin rpy="0 0 0" xyz="0.0 0.0 0.17"/>
    <parent link="xarm6_xarm_gripper_base_link"/>
    <child link="xarm6_ee_tip"/>
    <axis xyz="0 0 0"/>
  </joint> -->
  

  <gazebo>
    <plugin filename="libign_ros2_control-system.so" name="ign_ros2_control::IgnitionROS2ControlPlugin">
      <parameters>/tmp/controller_params_u2rc1p1x</parameters>
    </plugin>
  </gazebo>
  <!-- Insert at the end of xarm_device_macro.xacro -->
  <gazebo>
    <plugin filename="ignition-gazebo-pose-publisher-system" name="gz::sim::systems::PosePublisher">
      <publish_link_pose>false</publish_link_pose>
      <publish_visual_pose>false</publish_visual_pose>
      <publish_collision_pose>false</publish_collision_pose>
      <publish_sensor_pose>false</publish_sensor_pose>
      <publish_model_pose>true</publish_model_pose>
      <publish_nested_model_pose>true</publish_nested_model_pose>
      <use_pose_vector_msg>true</use_pose_vector_msg>
      <update_frequency>10</update_frequency>
      <static_publisher>false</static_publisher>
      <static_update_frequency>10</static_update_frequency>
    </plugin>
  </gazebo>
</robot>
